// 예외가 전달되는 동작 확인하기

#include <iostream>
using namespace std;

void func_throw(){
    cout << "func_throw()" << endl;
    cout << " throw -1 " << endl;
    throw -1;
    cout << " after throw -1 " << endl;
}

int main(){
    try{
        func_throw();
    }
    catch(int exec){
        cout << " catch " << exec << endl;
    }

    return 0;
}